#VRML_SIM R2025a utf8

EXTERNPROTO "https://raw.githubusercontent.com/cyberbotics/webots/R2025a/projects/objects/backgrounds/protos/TexturedBackground.proto"
EXTERNPROTO "https://raw.githubusercontent.com/cyberbotics/webots/R2025a/projects/objects/backgrounds/protos/TexturedBackgroundLight.proto"
EXTERNPROTO "https://raw.githubusercontent.com/cyberbotics/webots/R2025a/projects/objects/floors/protos/RectangleArena.proto"

WorldInfo {
}
Viewpoint {
  orientation -0.052342727623629716 -0.9165577452035643 0.396462026646029 5.585313451945447
  position -6.480912801166823 2.596508789187724 5.013535693069232
}
TexturedBackground {
}
TexturedBackgroundLight {
}
RectangleArena {
  translation -0.09 0 0.0300007
  rotation 0 1 0 5.30716e-06
  floorSize 4 4
}
DEF Obs1 Solid {
  translation 1.29137 0.234162 0.140315
  rotation -0.0025754902978973823 0.002671230308971273 0.9999931156654838 -1.5881053071795863
  children [
    Shape {
      appearance PBRAppearance {
      }
      geometry Box {
        size 1 0.05 0.5
      }
    }
  ]
}
DEF Obs1 Solid {
  translation -1.04559 -1.30584 0.128183
  rotation -0.002646061317764138 4.828432404606054e-05 0.9999964980079312 3.12429
  children [
    Shape {
      appearance PBRAppearance {
      }
      geometry Box {
        size 1 0.05 0.5
      }
    }
  ]
  name "solid(3)"
}
DEF Obs1 Solid {
  translation -1.00967 0.763914 0.128052
  rotation -0.002646061317764138 4.828432404606054e-05 0.9999964980079312 3.12429
  children [
    Shape {
      appearance PBRAppearance {
      }
      geometry Box {
        size 1 0.05 0.5
      }
    }
  ]
  name "solid(6)"
}
Robot {
  translation 1.8678007091934739 -1.4225736569841911 0.08482155415769128
  rotation -0.17584708991643835 -0.1564498026548889 -0.9719059935082026 1.5990347985051663
  children [
    DEF gps GPS {
      translation -0.05 -0.02 0.03
      children [
        Shape {
          appearance PBRAppearance {
          }
          geometry Cylinder {
            height 0.02
            radius 0.02
          }
        }
      ]
      boundingObject Shape {
        appearance PBRAppearance {
        }
        geometry Cylinder {
          height 0.02
          radius 0.02
        }
      }
      physics Physics {
      }
    }
    DEF lidar Lidar {
      translation 0.07 -0.02 0.04
      children [
        Shape {
          appearance PBRAppearance {
          }
          geometry Cylinder {
            height 0.025
            radius 0.025
          }
        }
      ]
      boundingObject Shape {
        appearance PBRAppearance {
        }
        geometry Cylinder {
          height 0.025
          radius 0.025
        }
      }
      physics Physics {
      }
      horizontalResolution 128
      fieldOfView 3.14
      verticalFieldOfView 0.1
      numberOfLayers 1
    }
    DEF BODY Shape {
      appearance PBRAppearance {
        baseColor 0.917647 0.145098 0.145098
        roughness 1
        metalness 0
      }
      geometry Box {
        size 0.2 0.1 0.05
      }
    }
    DEF WHEEL1 HingeJoint {
      jointParameters HingeJointParameters {
        position 68891.33052463496
        axis 0 1 0
        anchor 0.05 0.06 0
      }
      device [
        RotationalMotor {
          name "wheel1"
        }
      ]
      endPoint Solid {
        translation 0.0504057987936633 0.06043224674532349 0.0008122080786910091
        rotation 0.23321873474850285 0.6798875351064345 -0.6952423759878309 2.6822821746762497
        children [
          DEF WHEEL Shape {
            appearance PBRAppearance {
              baseColor 0.305882 0.898039 0.25098
              roughness 1
              metalness 0
            }
            geometry Cylinder {
              height 0.02
              radius 0.04
              subdivision 24
            }
          }
        ]
        boundingObject USE WHEEL
        physics Physics {
        }
        linearVelocity 0.00039227079394358027 -0.0026764502140276237 8.645250000897318e-05
        angularVelocity 2.997043497055063 -0.008704546581456599 -0.051039303292391335
      }
    }
    DEF WHEEL2 HingeJoint {
      jointParameters HingeJointParameters {
        position 41880.378348941915
        axis 0 1 0
        anchor 0.05 -0.06 0
      }
      device [
        RotationalMotor {
          name "wheel2"
        }
      ]
      endPoint Solid {
        translation 0.05000165751188478 -0.06000008469764562 -1.477812849036363e-06
        rotation 0.06840075909721328 0.7054493755782345 -0.7054519931584319 3.005004422979847
        children [
          USE WHEEL
        ]
        name "solid(1)"
        boundingObject USE WHEEL
        physics Physics {
        }
        linearVelocity 0.0003885839924401864 -0.0007136921469797224 0.00030126572914730265
        angularVelocity 9.995766179954911 -0.03162046511306582 -0.18694463044243753
      }
    }
    DEF WHEEL3 HingeJoint {
      jointParameters HingeJointParameters {
        position 68891.33628648879
        axis 0 1 0
        anchor -0.05 0.06 0
      }
      device [
        RotationalMotor {
          name "wheel3"
        }
      ]
      endPoint Solid {
        translation -0.049995531386900195 0.060000084994313085 1.2612878150759965e-06
        rotation -0.2314135333494276 -0.6879114374130824 0.6879139705362877 3.5964119487456783
        children [
          USE WHEEL
        ]
        name "solid(2)"
        boundingObject USE WHEEL
        physics Physics {
        }
        linearVelocity -0.00034004768423986746 0.00014171230650328033 -6.388275296873177e-05
        angularVelocity 2.997035850890689 -0.008701161324346045 -0.051042142270477986
      }
    }
    DEF WHEEL4 HingeJoint {
      jointParameters HingeJointParameters {
        position 41880.384734765896
        axis 0 1 0
        anchor -0.05 -0.06 0
      }
      device [
        RotationalMotor {
          name "wheel4"
        }
      ]
      endPoint Solid {
        translation -0.049998267606985274 -0.05999991499841628 -1.1914861369450284e-06
        rotation 0.0661379443286543 0.7055572521001112 -0.7055598743756055 3.0095096427036125
        children [
          USE WHEEL
        ]
        name "solid(3)"
        boundingObject USE WHEEL
        physics Physics {
        }
        linearVelocity -0.00032461191374753357 -0.000794396413038604 8.458705230909337e-05
        angularVelocity 9.995766180314714 -0.03162059078806017 -0.18694458289286792
      }
    }
    DEF DS_RIGHT DistanceSensor {
      translation 0.1 -0.03 0
      rotation 0 0 1 -0.3
      children [
        Shape {
          appearance PBRAppearance {
            baseColor 0.184314 0.596078 0.847059
            roughness 1
            metalness 0
          }
          geometry Box {
            size 0.01 0.01 0.01
          }
        }
      ]
      name "ds_right"
    }
    DEF DS_LEFT DistanceSensor {
      translation 0.1 0.03 0
      rotation 0 0 1 0.3
      children [
        Shape {
          appearance PBRAppearance {
            baseColor 0.184314 0.596078 0.847059
            roughness 1
            metalness 0
          }
          geometry Box {
            size 0.01 0.01 0.01
          }
        }
      ]
      name "ds_left"
    }
  ]
  boundingObject USE BODY
  physics Physics {
    density -1
    mass 1
  }
  controller "controlador"
  window "<none>"
  linearVelocity 4.263017600756951e-05 -0.00032579211527095824 0.0001675008550214627
  angularVelocity -0.0022950682115094375 0.0008911133105995346 0.0072576629321204275
}
Solid {
  translation 1.52 -1.01 0
  children [
    Shape {
      appearance PBRAppearance {
      }
      geometry Box {
        size 0.9 0.05 0.6
      }
    }
  ]
  name "solid(1)"
}
Solid {
  translation 0.39 -1.32 0.09
  rotation 0 0 1 4.6928012867022945e-06
  children [
    Shape {
      appearance PBRAppearance {
      }
      geometry Box {
        size 2 0.05 0.6
      }
    }
  ]
  name "solid(2)"
}
Solid {
  translation 0.39 0.75 0.09
  rotation 0 0 1 4.6928012867022945e-06
  children [
    Shape {
      appearance PBRAppearance {
      }
      geometry Box {
        size 2 0.05 0.6
      }
    }
  ]
  name "solid(5)"
}
Solid {
  translation -1.51 -0.3 0.09
  rotation 0 0 1 -1.5707953071795862
  children [
    Shape {
      appearance PBRAppearance {
      }
      geometry Box {
        size 2 0.05 0.6
      }
    }
  ]
  name "solid(4)"
}
